Workbook

Sheet Основные сведения + цели
A1: ФИО | B1: Ахмедова Дарья
A2: Должность | B2: Младший аналитик
A3: Наставник | B3: Самарцева София
A4: Руководитель | B4: Бизякина Наталья
A5: Проекты, в которых участвовал за последние полгода/год | B5: ='Самооценка сотрудника'!C2 -> РЖД: Миграция, СКИМ Ц. Программа обучения молодых специалистов.
A7: Важно обсудить на встрече
A8: ='Самооценка сотрудника'!B2 -> Обратную связь от коллег\наставников, точки роста.
C11: ☻
C13: ☹

Sheet Самооценка сотрудника
A1: Как тебя зовут? (фамилия, имя) | B1: Что тебе важно обсудить в рамках беседы о развитии? | C1: В каких проектах/других активностях ты участвовал в последние полгода-год? | D1: Насколько ты доволен своими результатами работы за прошедшие месяцы в компании? | E1: Какие свои успехи и достижения ты можешь выделить за последние полгода? Что особенно хорошо у тебя получается? | F1: Что не получилось осуществить за последние полгода? | G1: Куда бы ты сам/сама хотел развиваться? | H1: Выбери свою роль: | I1: Управление командой | J1: Управление проектом | K1: Если видишь свои зоны роста по компетенциям "управление проектом" или "управление командой", то укажи, какие именно: | L1: Устная и письменная коммуникация | M1: Если видишь свои зоны роста по компетенции "устная и письменная коммуникация", то укажи, какие именно: | N1: Выстраивание долгосрочных партнерских отношений | O1: Если видишь свои зоны роста по компетенции "выстраивание долгосрочных партнерских отношений", то укажи, какие именно: | P1: Взаимодействие в команде | Q1: Если видишь свои зоны роста по компетенции "взаимодействие в команде", то укажи, какие именно: | R1: Навыки переговоров в производственных ситуациях (в командах, с заказчиками) | S1: Если видишь свои зоны роста по компетенции " проведение переговоров в производственных ситуациях", то укажи, какие именно: | T1: Профессиональное обучение и личностное развитие | U1: Если видишь свои зоны роста по компетенции "профессиональное обучение и личностное развитие", то укажи, какие именно: | V1: Проведение и участие во встречах | W1: Если видишь свои зоны роста по компетенции "проведение и участие во встречах", то укажи, какие именно: | X1: Навыки презентаций ( продажа результатов, опыта, обучение) | Y1: Если видишь свои зоны роста по компетенции "проведение презентаций", то укажи, какие именно: | Z1: Ответственность | AA1: Если видишь свои зоны роста по компетенции "ответственность", то укажи, какие именно: | AB1: Содержание работы (развивающие и интересные задачи/ возможность проявить себя/ самостоятельность и наличие полномочий для решения задач) | AC1: Карьерный рост и возможности для него | AD1: Профессиональное развитие и возможности для него (наставничество, БОР, внешнее/внутреннее обучение, новые задачи) | AE1: Название и статус моей должности | AF1: Взаимоотношения с непосредственным руководителем: адекватность требований и отношений | AG1: Взаимоотношения с коллегами в команде | AH1: Корпоративная культура (корпоративные мероприятия, ценности, стратегия и т.д) | AI1: Уровень заработной платы (фиксированная часть/бонусы) | AJ1: Условия работы в компании (техническое обеспечение/формат работы/режим работы/объем загрузки)
A2: Ахмедова Дарья | B2: Обратную связь от коллег\наставников, точки роста. | C2: РЖД: Миграция, СКИМ Ц. Программа обучения молодых специалистов. | D2: 8 | E2: Коммуникации внутри команды. Наставничество внутри проекта. | F2: В рамках поставленных задач оцениваю свою работу, по большей части, положительно. Если выстраивать рейтинг от лучших к худшим показателям в своей работе, то на последнее место поставила бы ведение базы знаний. Вижу точки роста в написании качественного и понятного каждому текста. | G2: Не могу однозначно ответить на этот вопрос, так как он будет исходить исключительного из полученного опыта, а он пока небольшой и не весь функционал на должности опробован. На данный момент наставники предлагают мне возможности проявить себя в разных задачах, а я с радостью этой возможностью пользуюсь как раз для составления мнения о будущем развитии. Могу лишь сказать, что сейчас максимальную положительную эмоцию получаю от помощи в адаптации новичков на проекте и решении сложных кейсов, так как с каждым новым более глубоко погружаешься в проект. | H2: Участник проектной команды/ Специалист отдела (нет людей в подчинении) | L2: Четко, кратко и структурированно формулирует основную мысль коммуникации, в том числе в вопросах и ответах собеседников ;Владеет русским языком: пишет без грамматических, пунктуационных и стилистических ошибок ;Понимает разницу между каналами коммуникации (мессенджеры, почта, телефон) ;Своевременно предоставляет необходимую информацию и ответы ;Эффективно устанавливает контакт с собеседником вне зависимости от ситуации ;Всегда открыт на встречах, озвучивает появляющиеся вопросы, не откладывает коммуникацию "на потом";Обладает ясностью речи, нет слов-паразитов;Эмоционально устойчив в стрессовых коммуникациях: не заражается эмоциями, не переходит в наступательную / защитную позиции и ведет конструктивный диалог;В случае запроса к собеседнику четко указывает, что ожидается по результатам коммуникации и в какие сроки (какое действие, с каким результатом) ; | N2: При принятии решений придерживается не только своей точки зрения, но и других коллег/заказчика ;Объясняет необходимость и причины изменений/проясняет ситуацию коллегам/заказчикам на проекте ;Устраняет противоречия при помощи аргументов и логики, не переходит на личности ;Предоставляет помощь и поддержку команде;Честно и открыто излагает свою точку зрения в команде;Озвучивает и проговаривает ситуации, которые кажутся сложными и могут в дальнейшем провоцировать конфликт; | O2: Пропустила утверждения, где упоминался заказчик\клиент, так как имею малый опыт такой коммуникации. Здесь нужно еще себя проверить. | P2: Легко общается с людьми любого типа, находит общий язык со многими в проектной команде ;Активно участвует в командных обсуждениях;Всегда предупреждает: о своих отсутствиях на встречах, невозможности выполнить договоренности;Открыто говорит о сложностях, с которыми сталкивается в работе, и ищет для них решение; Вовлекает в обсуждение всех заинтересованных участников, учитывает мнение других при принятии решения;Выступает с предложениями по улучшению работы, предлагает варианты решения проблем ;Часто делится своими знаниями и опытом с другими коллегами;Замечает, когда другим нужна помощь и помогает при необходимости;Уважительно и спокойно воспринимает альтернативное мнение коллег;Подбадривает коллег или периодически разряжает напряженную ситуацию шуткой;Берет на себя лидерство в проектных встречах, руководит и направляет обсуждение ;Признает успех других, благодарит коллег за помощь и поддержку;Поддерживает коллег на проекте, при необходимости оказывает помощь;Формулирует и доносит правила работы в команде, которые помогают достигать лучшего результата. Пересматривает, делает исключения из правил, если они мешают достижению наилучшего результата; | R2: В обсуждениях разных точек зрения слушает и слышит позицию оппонента, задает открытые вопросы для прояснения его позиции ;Объясняет свою позицию с точки зрения ценности для проекта / команды / заказчика и приводит аргументы; Ищет компромиссные решения для достижения целей переговоров (идеально, если с позиции win-win);Формулирует свой взгляд на ситуацию, проблему;Ясно формулирует свою позицию и позицию 2 стороны (в переговорах, конфликтных ситуациях);Определяет, что для собеседника важно и предлагает варианты для достижения договоренностей. При возникновении разных позиций, интересов не вовлекается в конфронтацию, а проясняет позиции через открытые вопросы; | S2: Имею малый опыт коммуникации с заказчиком. | T2: Запрашивает и принимает обратную связь от других. Меняет свое поведение с учетом обратной связи ;Развивает технические навыки и отражает их в проектном резюме; Открыт новому опыту, проявляет гибкость: ищет и находит новые технологии, подходы, инструменты для улучшения работы;Осведомлен о трендах развития на рынке компетенций в части своего блока;Регулярно дает обратную связь команде; | V2: Организовывает (выбирает и согласовывает время, подбирает необходимых участников, формирует повестку и создает приглашение) и участвует в телефонных конференциях ;Играет роль модератора встречи: четко обозначает повестку, следит за временем, вовлекает необходимых участников в обсуждение, следит за тем, чтобы обсуждение шло согласно цели и возвращает к обсуждению, в случае если участники "уходят" с повестки; Фиксация результатов обсуждения в заданном проектом формате. Если формата нет, то может понятно сформулировать договоренности (действие, срок, ответственный и т п);Участвует в телефонных конференциях / встречах: способен четко предоставить информацию по заданной теме / вопросу;Оценивает в ходе эффективность проводимой встречи и при необходимости завершает ее с дальнейшим планом действий или планирует последующий логический follow up; | X2: Не имею опыта в навыках презентации; | Z2: Осуществляет регулярный мониторинг и контроль выполнения договоренностей, как со своей стороны, так и со стороны коллег ;Регулярно и системно следует запланированному графику и своевременно сообщает об изменениях/ статусе задачи; Занимает проактивную позицию в реализации проекта: делает все необходимое для достижения результата, предвидит и озвучивает риски, предпринимает действия направленные на успешное завершение проекта;Учится на своих ошибках и старается не совершать их в дальнейшем ;Своевременно и открыто заявляет о наличие возникших проблем;Проясняет какой конечный результат работы ожидается и в какой срок, фиксирует это.;В трудной ситуации ищет решение проблемы (собирает информацию, общается с разными людьми, изучает опыт за пределами компании);Продолжает предпринимать попытки добиться результата несмотря на неуспехи;Анализирует сложные ситуации, оценивает риски с целью разрешения ситуации;Анализирует прошлый период/завершенный проект, делает выводы и делится с коллегами;Соблюдает принятые на проекте правила (вовремя приходит на работу, соблюдает требования регламентов, заполняет отчеты), в том числе при взаимодействии с Заказчиком.; | AA2: Не всегда могу оценить возможные риски, но при повторении ситуации стараюсь повторной ошибки не допустить. | AB2: 10 | AC2: 10 | AD2: 10 | AE2: 10 | AF2: 10 | AG2: 10 | AH2: 10 | AI2: 9 | AJ2: 9
A5: Самооценка сотрудника
A6: Довлен своми результатами (1-10) | B6: =D2 -> 8 | C6: =10-B6 -> 2
A18: Мои успехи и достижения
A19: =E2 -> Коммуникации внутри команды. Наставничество внутри проекта.
A22: Что не получилось
A23: =F2 -> В рамках поставленных задач оцениваю свою работу, по большей части, положительно. Если выстраивать рейтинг от лучших к худшим показателям в своей работе, то на последнее место поставила бы ведение базы знаний. Вижу точки роста в написании качественного и понятного каждому текста.
A25: Куда хочу развиваться
A26: =G2 -> Не могу однозначно ответить на этот вопрос, так как он будет исходить исключительного из полученного опыта, а он пока небольшой и не весь функционал на должности опробован. На данный момент наставники предлагают мне возможности проявить себя в разных задачах, а я с радостью этой возможностью пользуюсь как раз для составления мнения о будущем развитии. Могу лишь сказать, что сейчас максимальную положительную эмоцию получаю от помощи в адаптации новичков на проекте и решении сложных кейсов, так как с каждым новым более глубоко погружаешься в проект.

Sheet Удовлетворенность сотрудника
A1: Самооценка сотрудника
A2: Содержание работы | B2: ='Самооценка сотрудника'!AB2 -> 10
A3: Карьерный рост и его возможности | B3: ='Самооценка сотрудника'!AC2 -> 10
A4: Профессиональное развитие и возможности для него | B4: ='Самооценка сотрудника'!AD2 -> 10
A5: Название и статус моей должности | B5: ='Самооценка сотрудника'!AE2 -> 10
A6: Взаимоотношения с руководителем | B6: ='Самооценка сотрудника'!AF2 -> 10
A7: Взаимоотношения с коллегами в команде | B7: ='Самооценка сотрудника'!AG2 -> 10
A8: Корпоративная культура | B8: ='Самооценка сотрудника'!AH2 -> 10
A9: Уровень заработной платы | B9: ='Самооценка сотрудника'!AI2 -> 9
A10: Условия работы в компании | B10: ='Самооценка сотрудника'!AJ2 -> 9

Sheet Оценка коллег
Z1: Письменная и устная коммуникация | AJ1: Выстраивание долгосрочных партнерских отношений | AV1: Взаимодействие в команде | BM1: Навыки переговоров | BT1: Профессиональное и личностное развитие | CA1: Ответственность | CM1: Проведение и участие во встречах | CS1: Навыки презентаций
A2: ак тебя зовут (фамилия, имя)? | B2: Укажи фамилию и имя коллеги, для которого даешь обратную связь? | C2: Как часто ты взаимодействуешь с коллегой? | D2: Если бы ты собирал свою проектную команду, то с какой вероятностью ты бы пригласил коллегу в проект? | E2: Прокомментируй свой ответ (обязательно при оценке ниже "7"): | F2: Выбери роль коллеги, на которого даешь обратную связь: | G2: Подбадривает, морально поддерживает и вдохновляет команду | H2: Старается быть в курсе задач, выполняемых каждым участником команды | I2: Поощряет инициативу со стороны всех членов команды, вовлекает в процесс тех, кто менее активен | J2: Информирует о своих решениях всех членов команды, с готовностью дает разъяснения | K2: Поручая задачу, учитывает квалификацию и опыт сотрудника | L2: Регулярно предоставляет обратную связь, основанную на фактах, а не на субъективных оценках | M2: Ставит четкие задачи, удостоверяется, что они поняты правильно, устанавливает параметры контроля, оговаривает сроки выполнения. | N2: Приветствует самостоятельный поиск решений сложных задач, дает возможности проявить себя | O2: Не оставляет без внимания мои заслуги, хвалит | P2: Озвучивает важность задач, выполняемых каждым членом команды для общего успеха | Q2: Прокомментируй свой ответ про позитивные или негативные проявления компетенции "Управление командой" | R2: Хорошо планирует работы по проекту, укладывается в сроки проекта | S2: Учитывает возможные риски по проекту, отслеживает их и предпринимает меры по снижению степени влияния рисков на результат проекта | T2: Контролирует промежуточные и конечные результаты работы участников проектов | U2: Рассказывает команде о долгосрочных целях проекта | V2: Организует регулярные групповые обсуждения и встречи для координации проекта | W2: Регулярно проводит ретро по проекту | X2: Организует неформальные встречи команды | Y2: Прокомментируй свой ответ про позитивные или негативные проявления компетенции "Управление проектом" | Z2: Четко, кратко и структурированно формулирует основную мысль коммуникации, в том числе в вопросах и ответах собеседников | AA2: Владеет русским языком: пишет без грамматических, пунктуационных и стилистических ошибок | AB2: Понимает разницу между каналами коммуникации (мессенджеры, почта, телефон) | AC2: Своевременно предоставляет необходимую информацию и ответы | AD2: Эффективно устанавливает контакт с собеседником вне зависимости от ситуации | AE2: Всегда открыт на встречах, озвучивает появляющиеся вопросы, не откладывает коммуникацию "на потом" | AF2: Обладает ясностью речи, нет слов-паразитов | AG2: Эмоционально устойчив в стрессовых коммуникациях: не заражается эмоциями, не переходит в наступательную / защитную позиции и ведет конструктивный диалог | AH2: В случае запроса к собеседнику четко указывает, что ожидается по результатам коммуникации и в какие сроки (какое действие, с каким результатом) | AI2: Прокомментируй свой ответ про позитивные или негативные проявления компетенции "устная и письменная коммуникация" | AJ2: При принятии решений придерживается не только своей точки зрения, но и других коллег/заказчика | AK2: Объясняет необходимость и причины изменений/проясняет ситуацию коллегам/заказчикам на проекте | AL2: При конфликте обсуждает возможные пути решения и ищет пути примирения с оппонентами | AM2: Устраняет противоречия при помощи аргументов и логики, не переходит на личности | AN2: Предоставляет помощь и поддержку команде | AO2: Понимает ценность выбранного решения для клиента, предпринимает действия для получения заказчиком этой ценности | AP2: Честно и открыто излагает свою точку зрения в команде | AQ2: Самостоятельно выявляет ценность для клиента и предлагает решения | AR2: Видит потребности клиента, которые выходят за скоуп проекта. Проясняет ценность этого для заказчика и возможные способы решения | AS2: Озвучивает и проговаривает ситуации, которые кажутся сложными и могут в дальнейшем провоцировать конфликт | AT2: Не избегает конфликта, помнит о целях и интересах проекта. Там, где это необходимо, не боится и отстаивает свою позицию (= не быть всегда на поводу у Клиента) | AU2: Прокомментируй свой ответ про позитивные или негативные проявления компетенции "выстраивание долгосрочных партнерских отношений" | AV2: Легко общается с людьми любого типа, находит общий язык со многими в проектной команде | AW2: Активно участвует в командных обсуждениях | AX2: Всегда предупреждает: о своих отсутствиях на встречах, невозможности выполнить договоренности | AY2: Открыто говорит о сложностях, с которыми сталкивается в работе, и ищет для них решение | AZ2: Вовлекает в обсуждение всех заинтересованных участников, учитывает мнение других при принятии решения | BA2: Выступает с предложениями по улучшению работы, предлагает варианты решения проблем | BB2: Часто делится своими знаниями и опытом с другими коллегами | BC2: Замечает, когда другим нужна помощь и помогает при необходимости | BD2: Уважительно и спокойно воспринимает альтернативное мнение коллег | BE2: Подбадривает коллег или периодически разряжает напряженную ситуацию шуткой | BF2: Берет на себя лидерство в проектных встречах, руководит и направляет обсуждение | BG2: Признает успех других, благодарит коллег за помощь и поддержку | BH2: Поддерживает коллег на проекте, при необходимости оказывает помощь | BI2: Поддерживает позитивную атмосферу в команде. Своевременно сообщает руководству проекта о риске возникновения конфликной ситуации в команде или с заказчиком. | BJ2: Формулирует и доносит правила работы в команде, которые помогают достигать лучшего результата. Пересматривает, делает исключения из правил, если они мешают достижению наилучшего результата | BK2: Выстраивает связи с рукодителеми других команд и центров компетенциий для успешной совместной работы | BL2: Прокомментируй свой ответ про позитивные или негативные проявления компетенции "взаимодействие в команде" | BM2: В обсуждениях разных точек зрения слушает и слышит позицию оппонента, задает открытые вопросы для прояснения его позиции | BN2: Объясняет свою позицию с точки зрения ценности для проекта / команды / заказчика и приводит аргументы | BO2: Ищет компромиссные решения для достижения целей переговоров (идеально, если с позиции win-win) | BP2: Формулирует свой взгляд на ситуацию, проблему | BQ2: Ясно формулирует свою позицию и позицию 2 стороны (в переговорах, конфликтных ситуациях) | BR2: Определяет, что для собеседника важно и предлагает варианты для достижения договоренностей. При возникновении разных позиций, интересов не вовлекается в конфронтацию, а проясняет позиции через отк... | BS2: Прокомментируй свой ответ про позитивные или негативные проявления компетенции "Навыки переговоров в производственных ситуациях (в командах, с заказчиками)" | BT2: Запрашивает и принимает обратную связь от других. Меняет свое поведение с учетом обратной связи | BU2: Развивает технические навыки и отражает их в проектном резюме | BV2: Открыт новому опыту, проявляет гибкость: ищет и находит новые технологии, подходы, инструменты для улучшения работы | BW2: Регулярно дает обратную связь команде | BX2: Осведомлен о трендах развития на рынке компетенций в части своего блока | BY2: Помогает выстроить трек развития: БОР, ИПР и пр. | BZ2: Прокомментируй свой ответ про позитивные или негативные проявления компетенции "Профессиональное обучение и личностное развитие" | CA2: Осуществляет регулярный мониторинг и контроль выполнения договоренностей, как со своей стороны, так и со стороны коллег | CB2: Регулярно и системно следует запланированному графику и своевременно сообщает об изменениях/ статусе задачи | CC2: Занимает проактивную позицию в реализации проекта: делает все необходимое для достижения результата, предвидит и озвучивает риски, предпринимает действия направленные на успешное завершение проекта | CD2: Учится на своих ошибках и старается не совершать их в дальнейшем | CE2: Своевременно и открыто заявляет о наличие возникших проблем | CF2: Проясняет какой конечный результат работы ожидается и в какой срок, фиксирует это. | CG2: В трудной ситуации ищет решение проблемы (собирает информацию, общается с разными людьми, изучает опыт за пределами компании) | CH2: Продолжает предпринимать попытки добиться результата несмотря на неуспехи | CI2: Анализирует сложные ситуации, оценивает риски с целью разрешения ситуации | CJ2: Анализирует прошлый период/завершенный проект, делает выводы и делится с коллегами | CK2: Соблюдает принятые на проекте правила (вовремя приходит на работу, соблюдает требования регламентов, заполняет отчеты), в том числе при взаимодействии с Заказчиком. | CL2: Прокомментируй свой ответ про позитивные или негативные проявления компетенции "Ответственность" | CM2: Участвует в телефонных конференциях / встречах: способен четко предоставить информацию по заданной теме / вопросу | CN2: Организовывает (выбирает и согласовывает время, подбирает необходимых участников, формирует повестку и создает приглашение) и участвует в телефонных конференциях | CO2: Играет роль модератора встречи: четко обозначает повестку, следит за временем, вовлекает необходимых участников в обсуждение, следит за тем, чтобы обсуждение шло согласно цели и возвращает к обсуж... | CP2: Фиксация результатов обсуждения в заданном проектом формате. Если формата нет, то может понятно сформулировать договоренности (действие, срок, ответственный и т п) | CQ2: Оценивает в ходе эффективность проводимой встречи и при необходимости завершает ее с дальнейшим планом действий или планирует последующий логический follow up | CR2: Прокомментируй свой ответ про позитивные или негативные проявления компетенции "Проведение и участие во встречах" | CS2: Формирует структуру и содержание презентации с учетом цели ее проведения. Уделяет внимание визуальной составляющей презентации (при необходимости) | CT2: Проводит презентацию, рассказывая основную мысль слайдов, но не зачитывая их. Удерживает внимание аудитории | CU2: Собирает обратную связь от аудитории. Отвечает на вопросы | CV2: Использует профессиональный язык и соответствующий стиль речи, адаптированные под формат аудитории | CW2: Прокомментируй свой ответ про позитивные или негативные проявления компетенции "Проведение презентаций" | CX2: На твой взгляд, какие зоны роста считаешь наиболее важными для развития коллеги на ближайшее время? | CY2: За что хотел бы поблагодарить/похвалить коллегу? | CZ2: Можем ли сотруднику сообщить, что обратная связь была именно от тебя? В случае, если сотруднику нужны будут пояснения по твоим комментариям.
A3: Крыжановская Елена | B3: Ахмедова Дарья | C3: часто (каждый день) | D3: 10 | CX3: зоны роста - это насмотренность и опыт, надо больше опыта | CY3: Даша большая молодец, вдохнула в нашу команду свежесть и инициативу, спасибо | CZ3: Готов дать комментарии сотруднику лично, пусть приходит - поясню.
A4: Макарова Анна | B4: Ахмедова Дарья | C4: периодически (1-2 раза в неделю) | D4: 10 | F4: Участник проектной команды/ Специалист отдела (нет людей в подчинении) | Z4: Да | AA4: Да | AB4: Да | AC4: Да | AD4: Да | AE4: Да | AF4: Да | AG4: Да | AH4: Да | AI4: Даша грамотно излагает свои мысли, доходчиво, ёмко и логично объясняет ответ на поставленный вопрос, кроме этого всегда подкрепляет логическую цепочку для нахождения правильного ответа. | AJ4: Да | AK4: Да | AL4: Да | AM4: Да | AN4: Да | AO4: Да | AP4: Да | AQ4: Да | AR4: Не могу оценить | AS4: Не могу оценить | AT4: Не могу оценить | AV4: Да | AW4: Да | AX4: Да | AY4: Да | AZ4: Да | BA4: Да | BB4: Да | BC4: Да | BD4: Да | BE4: Не могу оценить | BF4: Не могу оценить | BG4: Не могу оценить | BH4: Да | BI4: Не могу оценить | BJ4: Не могу оценить | BK4: Не могу оценить | BM4: Да | BN4: Да | BO4: Не могу оценить | BP4: Да | BQ4: Да | BR4: Да | BT4: Да | BU4: Не могу оценить | BV4: Не могу оценить | BW4: Не могу оценить | BX4: Не могу оценить | BY4: Не могу оценить | CA4: Не могу оценить | CB4: Да | CC4: Да | CD4: Да | CE4: Да | CF4: Да | CG4: Да | CH4: Да | CI4: Да | CJ4: Да | CK4: Да | CM4: Не могу оценить | CN4: Не могу оценить | CO4: Да | CP4: Да | CQ4: Да | CS4: Не могу оценить | CT4: Не могу оценить | CU4: Не могу оценить | CV4: Не могу оценить | CX4: У Дарьи есть уверенность в том, что она делает и хочет донести коллегам, способность подробно формулировать алгоритм действий в той или иной задаче, думаю, из нее получится хороший наставник (возможно попробует себя в роли наставника стажера). | CY4: Открытость, внимание к деталям | CZ4: Готов дать комментарии сотруднику лично, пусть приходит - поясню.
A5: Лера Мещерякова | B5: Даша Ахмедова | C5: часто (каждый день) | D5: 10 | F5: Участник проектной команды/ Специалист отдела (нет людей в подчинении) | Z5: Да | AA5: Да | AB5: Да | AC5: Да | AD5: Да | AE5: Да | AF5: Да | AG5: Да | AH5: Да | AJ5: Да | AK5: Да | AL5: Да | AM5: Да | AN5: Да | AO5: Да | AP5: Да | AQ5: Да | AR5: Да | AS5: Да | AT5: Да | AV5: Да | AW5: Да | AX5: Да | AY5: Да | AZ5: Да | BA5: Да | BB5: Да | BC5: Да | BD5: Да | BE5: Да | BF5: Да | BG5: Да | BH5: Да | BI5: Да | BJ5: Да | BK5: Да | BM5: Да | BN5: Да | BO5: Да | BP5: Да | BQ5: Да | BR5: Да | BT5: Да | BU5: Да | BV5: Да | BW5: Не могу оценить | BX5: Да | BY5: Нет | CA5: Да | CB5: Да | CC5: Да | CD5: Да | CE5: Да | CF5: Да | CG5: Да | CH5: Да | CI5: Да | CJ5: Да | CK5: Да | CM5: Да | CN5: Да | CO5: Да | CP5: Да | CQ5: Да | CS5: Не могу оценить | CT5: Не могу оценить | CU5: Не могу оценить | CV5: Не могу оценить | CX5: задачи СКИМ Ц/ЦЗ-1 | CY5: Благодарю Дашу за супер-ответственность и вовлеченность во все процессы. | CZ5: Готов дать комментарии сотруднику лично, пусть приходит - поясню.
A6: Ситдиков Аяз | B6: Ахмедова Дарья | C6: часто (каждый день) | D6: 8 | F6: Участник проектной команды/ Специалист отдела (нет людей в подчинении) | Z6: Да | AA6: Да | AB6: Да | AC6: Да | AD6: Да | AE6: Да | AF6: Да | AG6: Да | AH6: Да | AJ6: Не могу оценить | AK6: Да | AL6: Не могу оценить | AM6: Да | AN6: Да | AO6: Не могу оценить | AP6: Да | AQ6: Не могу оценить | AR6: Не могу оценить | AS6: Не могу оценить | AT6: Да | AV6: Да | AW6: Да | AX6: Да | AY6: Да | AZ6: Да | BA6: Да | BB6: Да | BC6: Не могу оценить | BD6: Да | BE6: Не могу оценить | BF6: Не могу оценить | BG6: Да | BH6: Да | BI6: Да | BJ6: Да | BK6: Да | BM6: Да | BN6: Да | BO6: Не могу оценить | BP6: Не могу оценить | BQ6: Да | BR6: Не могу оценить | BT6: Да | BU6: Не могу оценить | BV6: Не могу оценить | BW6: Да | BX6: Не могу оценить | BY6: Не могу оценить | CA6: Да | CB6: Да | CC6: Да | CD6: Не могу оценить | CE6: Да | CF6: Не могу оценить | CG6: Не могу оценить | CH6: Да | CI6: Не могу оценить | CJ6: Не могу оценить | CK6: Да | CM6: Не могу оценить | CN6: Не могу оценить | CO6: Не могу оценить | CP6: Не могу оценить | CQ6: Не могу оценить | CS6: Не могу оценить | CT6: Не могу оценить | CU6: Не могу оценить | CV6: Не могу оценить | CX6: С софт-скилами всё отлично, будет верным решением заниматься поднятием уровня хард-скилов. | CY6: За активную помощь в текущей задаче, заинтересованность. | CZ6: Готов дать комментарии сотруднику лично, пусть приходит - поясню.
A7: Марина | B7: Ахмедова | C7: часто (каждый день) | D7: 10 | E7: Дарья, объясняла мне реестры и вводила в курс дел на проекте "Миграция". Объяснение было четким и понятным, к ней всегда можно было обратиться за советом и получить ответ или понять куда обратиться далее для решения моей рабочей задачи. С Дарьей очень приятно работать. | F7: Участник проектной команды/ Специалист отдела (нет людей в подчинении) | Z7: Да | AA7: Да | AB7: Да | AC7: Да | AD7: Да | AE7: Да | AF7: Да | AG7: Да | AH7: Не могу оценить | AI7: При работе все было понятно. Коммуникация складывалась эффективно. | AJ7: Да | AK7: Не могу оценить | AL7: Не могу оценить | AM7: Да | AN7: Да | AO7: Не могу оценить | AP7: Да | AQ7: Не могу оценить | AR7: Не могу оценить | AS7: Да | AT7: Не могу оценить | AV7: Да | AW7: Да | AX7: Да | AY7: Да | AZ7: Да | BA7: Да | BB7: Да | BC7: Да | BD7: Да | BE7: Да | BF7: Да | BG7: Да | BH7: Да | BI7: Да | BJ7: Да | BK7: Да | BM7: Да | BN7: Да | BO7: Не могу оценить | BP7: Да | BQ7: Не могу оценить | BR7: Да | BT7: Да | BU7: Не могу оценить | BV7: Не могу оценить | BW7: Да | BX7: Не могу оценить | BY7: Не могу оценить | CA7: Не могу оценить | CB7: Да | CC7: Не могу оценить | CD7: Да | CE7: Да | CF7: Да | CG7: Да | CH7: Не могу оценить | CI7: Не могу оценить | CJ7: Не могу оценить | CK7: Не могу оценить | CM7: Не могу оценить | CN7: Не могу оценить | CO7: Не могу оценить | CP7: Не могу оценить | CQ7: Да | CS7: Не могу оценить | CT7: Не могу оценить | CU7: Да | CV7: Да | CX7: Возможно больше уверенности в своих знаниях и силах. У нее классно получается быть наставником и объяснять людям процессы и задачи | CY7: Спасибо за уделенное время для моей адаптации на проекте и в команде | CZ7: Готов дать комментарии сотруднику лично, пусть приходит - поясню.
A8: Леднев Эдуард | B8: Ахмедова | C8: часто (каждый день) | D8: 10 | F8: Участник проектной команды/ Специалист отдела (нет людей в подчинении) | Z8: Да | AA8: Да | AB8: Да | AC8: Да | AD8: Да | AE8: Да | AF8: Да | AG8: Да | AH8: Да | AJ8: Да | AK8: Да | AL8: Да | AM8: Да | AN8: Да | AO8: Да | AP8: Да | AQ8: Не могу оценить | AR8: Да | AS8: Да | AT8: Да | AV8: Да | AW8: Да | AX8: Да | AY8: Да | AZ8: Да | BA8: Да | BB8: Да | BC8: Да | BD8: Да | BE8: Да | BF8: Да | BG8: Да | BH8: Да | BI8: Да | BJ8: Да | BK8: Да | BM8: Да | BN8: Да | BO8: Да | BP8: Да | BQ8: Да | BR8: Да | BT8: Да | BU8: Да | BV8: Да | BW8: Да | BX8: Да | BY8: Да | CA8: Да | CB8: Да | CC8: Да | CD8: Да | CE8: Да | CF8: Да | CG8: Да | CH8: Да | CI8: Да | CJ8: Да | CK8: Да | CM8: Да | CN8: Да | CO8: Да | CP8: Да | CQ8: Да | CS8: Да | CT8: Да | CU8: Да | CV8: Да | CX8: уверенности в себе, а так молодец) | CY8: Активная, отзывчивая, хвалю за всё) | CZ8: Готов дать комментарии сотруднику лично, пусть приходит - поясню.
A9: Самарцева София | B9: Ахмедова Дарья | C9: часто (каждый день) | D9: 9 | F9: Участник проектной команды/ Специалист отдела (нет людей в подчинении) | Z9: Да | AA9: Да | AB9: Да | AC9: Да | AD9: Да | AE9: Да | AF9: Да | AG9: Да | AH9: Да | AI9: У Даши отличные навыки коммуникации, со всеми находит общий язык. | AJ9: Да | AK9: Да | AL9: Да | AM9: Да | AN9: Да | AO9: Не могу оценить | AP9: Да | AQ9: Не могу оценить | AR9: Не могу оценить | AS9: Не могу оценить | AT9: Не могу оценить | AV9: Да | AW9: Да | AX9: Да | AY9: Да | AZ9: Да | BA9: Да | BB9: Да | BC9: Да | BD9: Да | BE9: Да | BF9: Да | BG9: Да | BH9: Да | BI9: Да | BJ9: Не могу оценить | BK9: Не могу оценить | BL9: Даша имеет крепкую проактивную позицию в команде и берет на себя лидерскую позицию | BM9: Да | BN9: Да | BO9: Да | BP9: Да | BQ9: Да | BR9: Да | BT9: Да | BU9: Не могу оценить | BV9: Да | BW9: Не могу оценить | BX9: Не могу оценить | BY9: Не могу оценить | CA9: Да | CB9: Да | CC9: Да | CD9: Да | CE9: Да | CF9: Да | CG9: Да | CH9: Да | CI9: Да | CJ9: Да | CK9: Да | CM9: Да | CN9: Не могу оценить | CO9: Да | CP9: Да | CQ9: Да | CS9: Да | CT9: Не могу оценить | CU9: Не могу оценить | CV9: Да | CX9: 1) Повышение экспертного уровня в рамках проекта (наращивание объема знаний) | CY9: Отдельный лайк за краткое резюме при получении какой-либо информации) Хочу похвалить за: 1) Высокая ответственность и надежность 2) Готовность помочь коллегам и делиться знаниями 3) Хорошую адаптацию к новым (и не всегда легким) задачам 4) Качественную проработку задач | CZ9: Готов дать комментарии сотруднику лично, пусть приходит - поясню.
F25: Да | G25: =COUNTIF(G3:G24, "Да") -> 0 | H25: =COUNTIF(H3:H24, "Да") -> 0 | I25: =COUNTIF(I3:I24, "Да") -> 0 | J25: =COUNTIF(J3:J24, "Да") -> 0 | K25: =COUNTIF(K3:K24, "Да") -> 0 | L25: =COUNTIF(L3:L24, "Да") -> 0 | M25: =COUNTIF(M3:M24, "Да") -> 0 | N25: =COUNTIF(N3:N24, "Да") -> 0 | ... AT25: =COUNTIF(AT3:AT24, "Да") -> 3 | AV25: =COUNTIF(AV3:AV24, "Да") -> 6 | AW25: =COUNTIF(AW3:AW24, "Да") -> 6 | AX25: =COUNTIF(AX3:AX24, "Да") -> 6 | AY25: =COUNTIF(AY3:AY24, "Да") -> 6 | AZ25: =COUNTIF(AZ3:AZ24, "Да") -> 6 | BA25: =COUNTIF(BA3:BA24, "Да") -> 6 | BB25: =COUNTIF(BB3:BB24, "Да") -> 6 | BC25: =COUNTIF(BC3:BC24, "Да") -> 5 | ... BK25: =COUNTIF(BK3:BK24, "Да") -> 4 | BM25: =COUNTIF(BM3:BM24, "Да") -> 6 | BN25: =COUNTIF(BN3:BN24, "Да") -> 6 | BO25: =COUNTIF(BO3:BO24, "Да") -> 3 | BP25: =COUNTIF(BP3:BP24, "Да") -> 5 | BQ25: =COUNTIF(BQ3:BQ24, "Да") -> 5 | BR25: =COUNTIF(BR3:BR24, "Да") -> 5 | BS25: =COUNTIF(BS3:BS24, "Да") -> 0 | BT25: =COUNTIF(BT3:BT24, "Да") -> 6 | ... BY25: =COUNTIF(BY3:BY24, "Да") -> 1 | CA25: =COUNTIF(CA3:CA24, "Да") -> 4 | CB25: =COUNTIF(CB3:CB24, "Да") -> 6 | CC25: =COUNTIF(CC3:CC24, "Да") -> 5 | CD25: =COUNTIF(CD3:CD24, "Да") -> 5 | CE25: =COUNTIF(CE3:CE24, "Да") -> 6 | CF25: =COUNTIF(CF3:CF24, "Да") -> 5 | CG25: =COUNTIF(CG3:CG24, "Да") -> 5 | CH25: =COUNTIF(CH3:CH24, "Да") -> 5 | ... CK25: =COUNTIF(CK3:CK24, "Да") -> 5 | CM25: =COUNTIF(CM3:CM24, "Да") -> 3 | CN25: =COUNTIF(CN3:CN24, "Да") -> 2 | CO25: =COUNTIF(CO3:CO24, "Да") -> 4 | CP25: =COUNTIF(CP3:CP24, "Да") -> 4 | CQ25: =COUNTIF(CQ3:CQ24, "Да") -> 5 | CS25: =COUNTIF(CS3:CS24, "Да") -> 2 | CT25: =COUNTIF(CT3:CT24, "Да") -> 1 | CU25: =COUNTIF(CU3:CU24, "Да") -> 2 | CV25: =COUNTIF(CV3:CV24, "Да") -> 3
F26: Нет | G26: =COUNTIF(G3:G24, "Нет") -> 0 | H26: =COUNTIF(H3:H24, "Нет") -> 0 | I26: =COUNTIF(I3:I24, "Нет") -> 0 | J26: =COUNTIF(J3:J24, "Нет") -> 0 | K26: =COUNTIF(K3:K24, "Нет") -> 0 | L26: =COUNTIF(L3:L24, "Нет") -> 0 | M26: =COUNTIF(M3:M24, "Нет") -> 0 | N26: =COUNTIF(N3:N24, "Нет") -> 0 | ... AT26: =COUNTIF(AT3:AT24, "Нет") -> 0 | AV26: =COUNTIF(AV3:AV24, "Нет") -> 0 | AW26: =COUNTIF(AW3:AW24, "Нет") -> 0 | AX26: =COUNTIF(AX3:AX24, "Нет") -> 0 | AY26: =COUNTIF(AY3:AY24, "Нет") -> 0 | AZ26: =COUNTIF(AZ3:AZ24, "Нет") -> 0 | BA26: =COUNTIF(BA3:BA24, "Нет") -> 0 | BB26: =COUNTIF(BB3:BB24, "Нет") -> 0 | BC26: =COUNTIF(BC3:BC24, "Нет") -> 0 | ... BK26: =COUNTIF(BK3:BK24, "Нет") -> 0 | BM26: =COUNTIF(BM3:BM24, "Нет") -> 0 | BN26: =COUNTIF(BN3:BN24, "Нет") -> 0 | BO26: =COUNTIF(BO3:BO24, "Нет") -> 0 | BP26: =COUNTIF(BP3:BP24, "Нет") -> 0 | BQ26: =COUNTIF(BQ3:BQ24, "Нет") -> 0 | BR26: =COUNTIF(BR3:BR24, "Нет") -> 0 | BS26: =COUNTIF(BS3:BS24, "Нет") -> 0 | BT26: =COUNTIF(BT3:BT24, "Нет") -> 0 | ... BY26: =COUNTIF(BY3:BY24, "Нет") -> 1 | CA26: =COUNTIF(CA3:CA24, "Нет") -> 0 | CB26: =COUNTIF(CB3:CB24, "Нет") -> 0 | CC26: =COUNTIF(CC3:CC24, "Нет") -> 0 | CD26: =COUNTIF(CD3:CD24, "Нет") -> 0 | CE26: =COUNTIF(CE3:CE24, "Нет") -> 0 | CF26: =COUNTIF(CF3:CF24, "Нет") -> 0 | CG26: =COUNTIF(CG3:CG24, "Нет") -> 0 | CH26: =COUNTIF(CH3:CH24, "Нет") -> 0 | ... CK26: =COUNTIF(CK3:CK24, "Нет") -> 0 | CM26: =COUNTIF(CM3:CM24, "Нет") -> 0 | CN26: =COUNTIF(CN3:CN24, "Нет") -> 0 | CO26: =COUNTIF(CO3:CO24, "Нет") -> 0 | CP26: =COUNTIF(CP3:CP24, "Нет") -> 0 | CQ26: =COUNTIF(CQ3:CQ24, "Нет") -> 0 | CS26: =COUNTIF(CS3:CS24, "Нет") -> 0 | CT26: =COUNTIF(CT3:CT24, "Нет") -> 0 | CU26: =COUNTIF(CU3:CU24, "Нет") -> 0 | CV26: =COUNTIF(CV3:CV24, "Нет") -> 0
F27: Не могу оценить | G27: =COUNTIF(G3:G24, "Не могу оценить") -> 0 | H27: =COUNTIF(H3:H24, "Не могу оценить") -> 0 | I27: =COUNTIF(I3:I24, "Не могу оценить") -> 0 | J27: =COUNTIF(J3:J24, "Не могу оценить") -> 0 | K27: =COUNTIF(K3:K24, "Не могу оценить") -> 0 | L27: =COUNTIF(L3:L24, "Не могу оценить") -> 0 | M27: =COUNTIF(M3:M24, "Не могу оценить") -> 0 | N27: =COUNTIF(N3:N24, "Не могу оценить") -> 0 | ... AT27: =COUNTIF(AT3:AT24, "Не могу оценить") -> 3 | AV27: =COUNTIF(AV3:AV24, "Не могу оценить") -> 0 | AW27: =COUNTIF(AW3:AW24, "Не могу оценить") -> 0 | AX27: =COUNTIF(AX3:AX24, "Не могу оценить") -> 0 | AY27: =COUNTIF(AY3:AY24, "Не могу оценить") -> 0 | AZ27: =COUNTIF(AZ3:AZ24, "Не могу оценить") -> 0 | BA27: =COUNTIF(BA3:BA24, "Не могу оценить") -> 0 | BB27: =COUNTIF(BB3:BB24, "Не могу оценить") -> 0 | BC27: =COUNTIF(BC3:BC24, "Не могу оценить") -> 1 | ... BK27: =COUNTIF(BK3:BK24, "Не могу оценить") -> 2 | BM27: =COUNTIF(BM3:BM24, "Не могу оценить") -> 0 | BN27: =COUNTIF(BN3:BN24, "Не могу оценить") -> 0 | BO27: =COUNTIF(BO3:BO24, "Не могу оценить") -> 3 | BP27: =COUNTIF(BP3:BP24, "Не могу оценить") -> 1 | BQ27: =COUNTIF(BQ3:BQ24, "Не могу оценить") -> 1 | BR27: =COUNTIF(BR3:BR24, "Не могу оценить") -> 1 | BS27: =COUNTIF(BS3:BS24, "Не могу оценить") -> 0 | BT27: =COUNTIF(BT3:BT24, "Не могу оценить") -> 0 | ... BY27: =COUNTIF(BY3:BY24, "Не могу оценить") -> 4 | CA27: =COUNTIF(CA3:CA24, "Не могу оценить") -> 2 | CB27: =COUNTIF(CB3:CB24, "Не могу оценить") -> 0 | CC27: =COUNTIF(CC3:CC24, "Не могу оценить") -> 1 | CD27: =COUNTIF(CD3:CD24, "Не могу оценить") -> 1 | CE27: =COUNTIF(CE3:CE24, "Не могу оценить") -> 0 | CF27: =COUNTIF(CF3:CF24, "Не могу оценить") -> 1 | CG27: =COUNTIF(CG3:CG24, "Не могу оценить") -> 1 | CH27: =COUNTIF(CH3:CH24, "Не могу оценить") -> 1 | ... CK27: =COUNTIF(CK3:CK24, "Не могу оценить") -> 1 | CM27: =COUNTIF(CM3:CM24, "Не могу оценить") -> 3 | CN27: =COUNTIF(CN3:CN24, "Не могу оценить") -> 4 | CO27: =COUNTIF(CO3:CO24, "Не могу оценить") -> 2 | CP27: =COUNTIF(CP3:CP24, "Не могу оценить") -> 2 | CQ27: =COUNTIF(CQ3:CQ24, "Не могу оценить") -> 1 | CS27: =COUNTIF(CS3:CS24, "Не могу оценить") -> 4 | CT27: =COUNTIF(CT3:CT24, "Не могу оценить") -> 5 | CU27: =COUNTIF(CU3:CU24, "Не могу оценить") -> 4 | CV27: =COUNTIF(CV3:CV24, "Не могу оценить") -> 3
F28: Да | G28: =G25/COUNTA($F$3:$F$24) -> 0 | H28: =H25/COUNTA($F$3:$F$24) -> 0 | I28: =I25/COUNTA($F$3:$F$24) -> 0 | J28: =J25/COUNTA($F$3:$F$24) -> 0 | K28: =K25/COUNTA($F$3:$F$24) -> 0 | L28: =L25/COUNTA($F$3:$F$24) -> 0 | M28: =M25/COUNTA($F$3:$F$24) -> 0 | N28: =N25/COUNTA($F$3:$F$24) -> 0 | ... AT28: =AT25/COUNTA($F$3:$F$24) -> 0.5 | AV28: =AV25/COUNTA($F$3:$F$24) -> 1 | AW28: =AW25/COUNTA($F$3:$F$24) -> 1 | AX28: =AX25/COUNTA($F$3:$F$24) -> 1 | AY28: =AY25/COUNTA($F$3:$F$24) -> 1 | AZ28: =AZ25/COUNTA($F$3:$F$24) -> 1 | BA28: =BA25/COUNTA($F$3:$F$24) -> 1 | BB28: =BB25/COUNTA($F$3:$F$24) -> 1 | BC28: =BC25/COUNTA($F$3:$F$24) -> 0.83333333 | ... BK28: =BK25/COUNTA($F$3:$F$24) -> 0.66666667 | BM28: =BM25/COUNTA($F$3:$F$24) -> 1 | BN28: =BN25/COUNTA($F$3:$F$24) -> 1 | BO28: =BO25/COUNTA($F$3:$F$24) -> 0.5 | BP28: =BP25/COUNTA($F$3:$F$24) -> 0.83333333 | BQ28: =BQ25/COUNTA($F$3:$F$24) -> 0.83333333 | BR28: =BR25/COUNTA($F$3:$F$24) -> 0.83333333 | BS28: =BS25/COUNTA($F$3:$F$24) -> 0 | BT28: =BT25/COUNTA($F$3:$F$24) -> 1 | ... BY28: =BY25/COUNTA($F$3:$F$24) -> 0.16666667 | CA28: =CA25/COUNTA($F$3:$F$24) -> 0.66666667 | CB28: =CB25/COUNTA($F$3:$F$24) -> 1 | CC28: =CC25/COUNTA($F$3:$F$24) -> 0.83333333 | CD28: =CD25/COUNTA($F$3:$F$24) -> 0.83333333 | CE28: =CE25/COUNTA($F$3:$F$24) -> 1 | CF28: =CF25/COUNTA($F$3:$F$24) -> 0.83333333 | CG28: =CG25/COUNTA($F$3:$F$24) -> 0.83333333 | CH28: =CH25/COUNTA($F$3:$F$24) -> 0.83333333 | ... CK28: =CK25/COUNTA($F$3:$F$24) -> 0.83333333 | CM28: =CM25/COUNTA($F$3:$F$24) -> 0.5 | CN28: =CN25/COUNTA($F$3:$F$24) -> 0.33333333 | CO28: =CO25/COUNTA($F$3:$F$24) -> 0.66666667 | CP28: =CP25/COUNTA($F$3:$F$24) -> 0.66666667 | CQ28: =CQ25/COUNTA($F$3:$F$24) -> 0.83333333 | CS28: =CS25/COUNTA($F$3:$F$24) -> 0.33333333 | CT28: =CT25/COUNTA($F$3:$F$24) -> 0.16666667 | CU28: =CU25/COUNTA($F$3:$F$24) -> 0.33333333 | CV28: =CV25/COUNTA($F$3:$F$24) -> 0.5
F29: Нет | G29: =G26/COUNTA($F$3:$F$24) -> 0 | H29: =H26/COUNTA($F$3:$F$24) -> 0 | I29: =I26/COUNTA($F$3:$F$24) -> 0 | J29: =J26/COUNTA($F$3:$F$24) -> 0 | K29: =K26/COUNTA($F$3:$F$24) -> 0 | L29: =L26/COUNTA($F$3:$F$24) -> 0 | M29: =M26/COUNTA($F$3:$F$24) -> 0 | N29: =N26/COUNTA($F$3:$F$24) -> 0 | ... AT29: =AT26/COUNTA($F$3:$F$24) -> 0 | AV29: =AV26/COUNTA($F$3:$F$24) -> 0 | AW29: =AW26/COUNTA($F$3:$F$24) -> 0 | AX29: =AX26/COUNTA($F$3:$F$24) -> 0 | AY29: =AY26/COUNTA($F$3:$F$24) -> 0 | AZ29: =AZ26/COUNTA($F$3:$F$24) -> 0 | BA29: =BA26/COUNTA($F$3:$F$24) -> 0 | BB29: =BB26/COUNTA($F$3:$F$24) -> 0 | BC29: =BC26/COUNTA($F$3:$F$24) -> 0 | ... BK29: =BK26/COUNTA($F$3:$F$24) -> 0 | BM29: =BM26/COUNTA($F$3:$F$24) -> 0 | BN29: =BN26/COUNTA($F$3:$F$24) -> 0 | BO29: =BO26/COUNTA($F$3:$F$24) -> 0 | BP29: =BP26/COUNTA($F$3:$F$24) -> 0 | BQ29: =BQ26/COUNTA($F$3:$F$24) -> 0 | BR29: =BR26/COUNTA($F$3:$F$24) -> 0 | BS29: =BS26/COUNTA($F$3:$F$24) -> 0 | BT29: =BT26/COUNTA($F$3:$F$24) -> 0 | ... BY29: =BY26/COUNTA($F$3:$F$24) -> 0.16666667 | CA29: =CA26/COUNTA($F$3:$F$24) -> 0 | CB29: =CB26/COUNTA($F$3:$F$24) -> 0 | CC29: =CC26/COUNTA($F$3:$F$24) -> 0 | CD29: =CD26/COUNTA($F$3:$F$24) -> 0 | CE29: =CE26/COUNTA($F$3:$F$24) -> 0 | CF29: =CF26/COUNTA($F$3:$F$24) -> 0 | CG29: =CG26/COUNTA($F$3:$F$24) -> 0 | CH29: =CH26/COUNTA($F$3:$F$24) -> 0 | ... CK29: =CK26/COUNTA($F$3:$F$24) -> 0 | CM29: =CM26/COUNTA($F$3:$F$24) -> 0 | CN29: =CN26/COUNTA($F$3:$F$24) -> 0 | CO29: =CO26/COUNTA($F$3:$F$24) -> 0 | CP29: =CP26/COUNTA($F$3:$F$24) -> 0 | CQ29: =CQ26/COUNTA($F$3:$F$24) -> 0 | CS29: =CS26/COUNTA($F$3:$F$24) -> 0 | CT29: =CT26/COUNTA($F$3:$F$24) -> 0 | CU29: =CU26/COUNTA($F$3:$F$24) -> 0 | CV29: =CV26/COUNTA($F$3:$F$24) -> 0
F30: Не могу оценить | G30: =G27/COUNTA($F$3:$F$24) -> 0 | H30: =H27/COUNTA($F$3:$F$24) -> 0 | I30: =I27/COUNTA($F$3:$F$24) -> 0 | J30: =J27/COUNTA($F$3:$F$24) -> 0 | K30: =K27/COUNTA($F$3:$F$24) -> 0 | L30: =L27/COUNTA($F$3:$F$24) -> 0 | M30: =M27/COUNTA($F$3:$F$24) -> 0 | N30: =N27/COUNTA($F$3:$F$24) -> 0 | ... AT30: =AT27/COUNTA($F$3:$F$24) -> 0.5 | AV30: =AV27/COUNTA($F$3:$F$24) -> 0 | AW30: =AW27/COUNTA($F$3:$F$24) -> 0 | AX30: =AX27/COUNTA($F$3:$F$24) -> 0 | AY30: =AY27/COUNTA($F$3:$F$24) -> 0 | AZ30: =AZ27/COUNTA($F$3:$F$24) -> 0 | BA30: =BA27/COUNTA($F$3:$F$24) -> 0 | BB30: =BB27/COUNTA($F$3:$F$24) -> 0 | BC30: =BC27/COUNTA($F$3:$F$24) -> 0.16666667 | ... BK30: =BK27/COUNTA($F$3:$F$24) -> 0.33333333 | BM30: =BM27/COUNTA($F$3:$F$24) -> 0 | BN30: =BN27/COUNTA($F$3:$F$24) -> 0 | BO30: =BO27/COUNTA($F$3:$F$24) -> 0.5 | BP30: =BP27/COUNTA($F$3:$F$24) -> 0.16666667 | BQ30: =BQ27/COUNTA($F$3:$F$24) -> 0.16666667 | BR30: =BR27/COUNTA($F$3:$F$24) -> 0.16666667 | BS30: =BS27/COUNTA($F$3:$F$24) -> 0 | BT30: =BT27/COUNTA($F$3:$F$24) -> 0 | ... BY30: =BY27/COUNTA($F$3:$F$24) -> 0.66666667 | CA30: =CA27/COUNTA($F$3:$F$24) -> 0.33333333 | CB30: =CB27/COUNTA($F$3:$F$24) -> 0 | CC30: =CC27/COUNTA($F$3:$F$24) -> 0.16666667 | CD30: =CD27/COUNTA($F$3:$F$24) -> 0.16666667 | CE30: =CE27/COUNTA($F$3:$F$24) -> 0 | CF30: =CF27/COUNTA($F$3:$F$24) -> 0.16666667 | CG30: =CG27/COUNTA($F$3:$F$24) -> 0.16666667 | CH30: =CH27/COUNTA($F$3:$F$24) -> 0.16666667 | ... CK30: =CK27/COUNTA($F$3:$F$24) -> 0.16666667 | CM30: =CM27/COUNTA($F$3:$F$24) -> 0.5 | CN30: =CN27/COUNTA($F$3:$F$24) -> 0.66666667 | CO30: =CO27/COUNTA($F$3:$F$24) -> 0.33333333 | CP30: =CP27/COUNTA($F$3:$F$24) -> 0.33333333 | CQ30: =CQ27/COUNTA($F$3:$F$24) -> 0.16666667 | CS30: =CS27/COUNTA($F$3:$F$24) -> 0.66666667 | CT30: =CT27/COUNTA($F$3:$F$24) -> 0.83333333 | CU30: =CU27/COUNTA($F$3:$F$24) -> 0.66666667 | CV30: =CV27/COUNTA($F$3:$F$24) -> 0.5
A40: Письменная и устная коммуникация
A41: Примеры, если что-то не так
A42: =_xlfn.TEXTJOIN(" ",1,AI3:AI23) -> Даша грамотно излагает свои мысли, доходчиво, ёмко и логично объясняет ответ на поставленный вопрос, кроме этого всегда подкрепляет логическую цепочку для нахождения правильного ответа. При работе все было понятно. Коммуникация складывалась эффективно. У Даши отличные навыки коммуникации, со всеми находит общий язык.
A46: Выстраивание долгосрочных партнерских отношений
A47: Примеры, если что-то не так
A48: =_xlfn.TEXTJOIN(" ",1,AU3:AU23)
A52: Взаимодействие в команде
A53: Примеры, если что-то не так
A54: =_xlfn.TEXTJOIN(" ",1,BL3:BL23) -> Даша имеет крепкую проактивную позицию в команде и берет на себя лидерскую позицию
A58: Ответственность
A59: Примеры, если что-то не так
A60: =_xlfn.TEXTJOIN(" ",1,CL3:CL23)
A64: Навыки переговоров в производстенных ситуациях
A65: Примеры, если что-то не так
A66: =_xlfn.TEXTJOIN(" ",1,BS3:BS23)
A68: Проведение и участие во встречах
A69: Примеры, если что-то не так
A70: =_xlfn.TEXTJOIN(" ",1,CR3:CR23)
A73: Профессиональное обучение и личностное развитие
A74: Примеры, если что-то не так
A75: =_xlfn.TEXTJOIN(" ",1,'Оценка коллег'!BZ3:BZ8)
A79: Управление командой
A80: Примеры, если что-то не так
A81: =_xlfn.TEXTJOIN(" ",1,Q3:Q24)
A85: Управление проектом
...

Sheet Коллеги_%
A9: Оценка
A10: Пригласил бы в команду (1-10) | B10: =AVERAGE('Оценка коллег'!D3:D24) -> 9.5714286 | C10: =10-B10 -> 0.42857143
A24: Устная и письменная коммуникация | B24: Сотрудник | C24: Да | D24: Нет | E24: Не могу оценить
A25: 1.Четко, кратко и структурированно формулирует основную мысль коммуникации, в том числе в вопросах и ответах собеседников | B25: ✔ | C25: ='Оценка коллег'!Z28 -> 1 | D25: ='Оценка коллег'!Z29 -> 0 | E25: ='Оценка коллег'!Z30 -> 0
A26: 2. Владеет русским языком: пишет без грамматических, пунктуационных и стилистических ошибок | B26: ✔ | C26: ='Оценка коллег'!AA28 -> 1 | D26: ='Оценка коллег'!AA29 -> 0 | E26: ='Оценка коллег'!AA30 -> 0
A27: 3. Понимает разницу между каналами коммуникации (мессенджеры, почта, телефон) | B27: ✔ | C27: ='Оценка коллег'!AB28 -> 1 | D27: ='Оценка коллег'!AB29 -> 0 | E27: ='Оценка коллег'!AB30 -> 0
A28: 4. Своевременно предоставляет необходимую информацию и ответы | B28: ✔ | C28: ='Оценка коллег'!AC28 -> 1 | D28: ='Оценка коллег'!AC29 -> 0 | E28: ='Оценка коллег'!AC30 -> 0
A29: 5. Эффективно устанавливает контакт с собеседником вне зависимости от ситуации | B29: ✔ | C29: ='Оценка коллег'!AD28 -> 1 | D29: ='Оценка коллег'!AD29 -> 0 | E29: ='Оценка коллег'!AD30 -> 0
A30: 6. Всегда открыт на встречах, озвучивает появляющиеся вопросы, не откладывает коммуникацию "на потом" | B30: ✔ | C30: ='Оценка коллег'!AE28 -> 1 | D30: ='Оценка коллег'!AE29 -> 0 | E30: ='Оценка коллег'!AE30 -> 0
A31: 7. Обладает ясностью речи, нет слов-паразитов | B31: ✔ | C31: ='Оценка коллег'!AF28 -> 1 | D31: ='Оценка коллег'!AF29 -> 0 | E31: ='Оценка коллег'!AF30 -> 0
A32: 8. Эмоционально устойчив в стрессовых коммуникациях: не заражается эмоциями, не переходит в наступательную / защитную позиции и ведет конструктивный диалог | B32: ✔ | C32: ='Оценка коллег'!AG28 -> 1 | D32: ='Оценка коллег'!AG29 -> 0 | E32: ='Оценка коллег'!AG30 -> 0
A33: 9. В случае запроса к собеседнику четко указывает, что ожидается по результатам коммуникации и в какие сроки (какое действие, с каким результатом) | B33: ✔ | C33: ='Оценка коллег'!AH28 -> 0.83333333 | D33: ='Оценка коллег'!AH29 -> 0 | E33: ='Оценка коллег'!AH30 -> 0.16666667
A34: Другое:
A39: Выстраивание долгосрочных партнерских отношений | B39: Сотрудник | C39: Да | D39: Нет | E39: Не могу оценить
A40: 1. При принятии решений придерживается не только своей точки зрения, но и других коллег/заказчика | B40: ✔ | C40: ='Оценка коллег'!AJ28 -> 0.83333333 | D40: ='Оценка коллег'!AJ29 -> 0 | E40: ='Оценка коллег'!AJ30 -> 0.16666667
A41: 2. Объясняет необходимость и причины изменений/проясняет ситуацию коллегам/заказчикам на проекте | B41: ✔ | C41: ='Оценка коллег'!AK28 -> 0.83333333 | D41: ='Оценка коллег'!AK29 -> 0 | E41: ='Оценка коллег'!AK30 -> 0.16666667
A42: 3. При конфликте обсуждает возможные пути решения и ищет пути примирения с оппонентами | C42: ='Оценка коллег'!AL28 -> 0.66666667 | D42: ='Оценка коллег'!AL29 -> 0 | E42: ='Оценка коллег'!AL30 -> 0.33333333
A43: 4. Устраняет противоречия при помощи аргументов и логики, не переходит на личности | B43: ✔ | C43: ='Оценка коллег'!AM28 -> 1 | D43: ='Оценка коллег'!AM29 -> 0 | E43: ='Оценка коллег'!AM30 -> 0
A44: 5. Предоставляет помощь и поддержку команде | B44: ✔ | C44: ='Оценка коллег'!AN28 -> 1 | D44: ='Оценка коллег'!AN29 -> 0 | E44: ='Оценка коллег'!AN30 -> 0
A45: 6. Понимает ценность выбранного решения для клиента, предпринимает действия для получения заказчиком этой ценности | C45: ='Оценка коллег'!AO28 -> 0.5 | D45: ='Оценка коллег'!AO29 -> 0 | E45: ='Оценка коллег'!AO30 -> 0.5
A46: 7. Честно и открыто излагает свою точку зрения в команде | B46: ✔ | C46: ='Оценка коллег'!AP28 -> 1 | D46: ='Оценка коллег'!AP29 -> 0 | E46: ='Оценка коллег'!AP30 -> 0
A47: 8. Самостоятельно выявляет ценность для клиента и предлагает решения | C47: ='Оценка коллег'!AQ28 -> 0.33333333 | D47: ='Оценка коллег'!AQ29 -> 0 | E47: ='Оценка коллег'!AQ30 -> 0.66666667
A48: 9. Видит потребности клиента, которые выходят за скоуп проекта. Проясняет ценность этого для заказчика и возможные способы решения | C48: ='Оценка коллег'!AR28 -> 0.33333333 | D48: ='Оценка коллег'!AR29 -> 0 | E48: ='Оценка коллег'!AR30 -> 0.66666667
A49: 10. Озвучивает и проговаривает ситуации, которые кажутся сложными и могут в дальнейшем провоцировать конфликт | B49: ✔ | C49: ='Оценка коллег'!AS28 -> 0.5 | D49: ='Оценка коллег'!AS29 -> 0 | E49: ='Оценка коллег'!AS30 -> 0.5
A50: 11. Не избегает конфликта, помнит о целях и интересах проекта. Там, где это необходимо, не боится и отстаивает свою позицию (= не быть всегда на поводу у Клиента) | C50: ='Оценка коллег'!AT28 -> 0.5 | D50: ='Оценка коллег'!AT29 -> 0 | E50: ='Оценка коллег'!AT30 -> 0.5
A51: Другое: Пропустила утверждения, где упоминался заказчик\клиент, так как имею малый опыт такой коммуникации. Здесь нужно еще себя проверить.
A54: Взаимодействие в команде | B54: Сотрудник | C54: Да | D54: Нет | E54: Не могу оценить
A55: 1. Легко общается с людьми любого типа, находит общий язык со многими в проектной команде | B55: ✔ | C55: ='Оценка коллег'!AV28 -> 1 | D55: ='Оценка коллег'!AV29 -> 0 | E55: ='Оценка коллег'!AV30 -> 0
A56: 2.Активно участвует в командных обсуждениях | B56: ✔ | C56: ='Оценка коллег'!AW28 -> 1 | D56: ='Оценка коллег'!AW29 -> 0 | E56: ='Оценка коллег'!AW30 -> 0
A57: 3. Всегда предупреждает: о своих отсутствиях на встречах, невозможности выполнить договоренности | B57: ✔ | C57: ='Оценка коллег'!AX28 -> 1 | D57: ='Оценка коллег'!AX29 -> 0 | E57: ='Оценка коллег'!AX30 -> 0
A58: 4. Открыто говорит о сложностях, с которыми сталкивается в работе, и ищет для них решение | B58: ✔ | C58: ='Оценка коллег'!AY28 -> 1 | D58: ='Оценка коллег'!AY29 -> 0 | E58: ='Оценка коллег'!AY30 -> 0
A59: 5. Вовлекает в обсуждение всех заинтересованных участников, учитывает мнение других при принятии решения | B59: ✔ | C59: ='Оценка коллег'!AZ28 -> 1 | D59: ='Оценка коллег'!AZ29 -> 0 | E59: ='Оценка коллег'!AZ30 -> 0
A60: 6. Выступает с предложениями по улучшению работы, предлагает варианты решения проблем | B60: ✔ | C60: ='Оценка коллег'!BA28 -> 1 | D60: ='Оценка коллег'!BA29 -> 0 | E60: ='Оценка коллег'!BA30 -> 0
A61: 7. Часто делится своими знаниями и опытом с другими коллегами | B61: ✔ | C61: ='Оценка коллег'!BB28 -> 1 | D61: ='Оценка коллег'!BB29 -> 0 | E61: ='Оценка коллег'!BB30 -> 0
A62: 8. Замечает, когда другим нужна помощь и помогает при необходимости | B62: ✔ | C62: ='Оценка коллег'!BC28 -> 0.83333333 | D62: ='Оценка коллег'!BC29 -> 0 | E62: ='Оценка коллег'!BC30 -> 0.16666667
A63: 9. Уважительно и спокойно воспринимает альтернативное мнение коллег | B63: ✔ | C63: ='Оценка коллег'!BD28 -> 1 | D63: ='Оценка коллег'!BD29 -> 0 | E63: ='Оценка коллег'!BD30 -> 0
A64: 10. Подбадривает коллег или периодически разряжает напряженную ситуацию шуткой | B64: ✔ | C64: ='Оценка коллег'!BE28 -> 0.66666667 | D64: ='Оценка коллег'!BE29 -> 0 | E64: ='Оценка коллег'!BE30 -> 0.33333333
A65: 11. Берет на себя лидерство в проектных встречах, руководит и направляет обсуждение | B65: ✔ | C65: ='Оценка коллег'!BF28 -> 0.66666667 | D65: ='Оценка коллег'!BF29 -> 0 | E65: ='Оценка коллег'!BF30 -> 0.33333333
A66: 12. Признает успех других, благодарит коллег за помощь и поддержку | B66: ✔ | C66: ='Оценка коллег'!BG28 -> 0.83333333 | D66: ='Оценка коллег'!BG29 -> 0 | E66: ='Оценка коллег'!BG30 -> 0.16666667
A67: 13. Поддерживает коллег на проекте, при необходимости оказывает помощь | B67: ✔ | C67: ='Оценка коллег'!BH28 -> 1 | D67: ='Оценка коллег'!BH29 -> 0 | E67: ='Оценка коллег'!BH30 -> 0
...

Sheet Матрица1
A1: УРОВЕНЬ | C1: JUNIOR (МЛАДШИЙ) | E1: MIDDLE (СРЕДНИЙ / ПРОСТО АНАЛИТИК) | G1: SENIOR (СТАРШИЙ) | I1: LEAD (ВЕДУЩИЙ) | K1: TEAMLEAD (РУК. ГРУППЫ)
A2: 0 Индикативный срок при стремлении профессионального роста | C2: • min 6 мес и до 1,5 лет. В среднем 9-12 мес | E2: • 2-3 года | G2: • 3-5 лет | I2: • Индивидуально | K2: • Индивидуально
A3: 1 ПИСЬМЕННАЯ КОММУНИКАЦИЯ | B3: ='Оценка коллег'!AA28 -> 1 | C3: 1. Владеет русским языком: пишет без грамматических, пунктуационных и стилистических ошибок | D3: ='Оценка коллег'!Z28 -> 1 | E3: 1. Четко, кратно и структурированно формулирует основную мысль коммуникации, в том числе в вопросах и ответах собеседников | F3: ='Оценка коллег'!AG29 -> 0 | G3: 1. В случае запроса к собеседнику четко указывать, что ожидается по результатам коммуникации и в какие сроки (какое действие, с каким результатом)
B4: ='Оценка коллег'!AC28 -> 1 | C4: 2. Своевременно предоставляет необходимую информацию и ответы: проектные вопросы - в течение дня или согласно SLA проекта, другие - согласно требованиям. Если срок не указан, то разумный подход (не более 2 раб дней) | D4: ='Оценка коллег'!AB28 -> 1 | E4: 2. Понимает разницу между каналами коммуникации (мессенджеры, почта, телефон) адаптирует свой стиль общения в зависимости от выбранного канала
A5: 2 УСТНАЯ КОММУНИКАЦИЯ | B5: ='Коллеги_%'!C30 -> 1 | C5: 1. Всегда открыт на встречах, озвучивает появляющиеся вопросы, не откладывает коммуникацию “на потом” | D5: ='Коллеги_%'!C29 -> 1 | E5: 1. Эффективно устанавливает контакт с собеседником вне зависимости от ситуации = ведет беседу согласно цели коммуникации | F5: ='Коллеги_%'!C32 -> 1 | G5: 1. Эмоционально устойчив в стрессовых коммуникациях: не заражается эмоциями, не переходит в наступательную / защитную позиции и ведет конструктивный диалог
D6: ='Коллеги_%'!C31 -> 1 | E6: 2. Обладает ясностью речи: нет слов-паразитов, слова произносятся внятно и полностью. Изьясняется простыми для понимания предложениями
A7: 3 ВЫСТРАИВАНИЕ ДОЛГОСРОЧНЫХ ПАРТНЁРСКИХ ОТНОШЕНИЙ | B7: ='Коллеги_%'!C49 -> 0.5 | C7: 1. Озвучивает и проговаривает ситуации, которые кажутся сложными и могут в дальнейшем провоцировать конфликт | D7: ='Коллеги_%'!C40 -> 0.83333333 | E7: 1. При принятии решений придерживается не только своей точки зрения, обращает внимание на аргументы, учитывает точку зрения всех коллег/ заказчиков | F7: ='Коллеги_%'!C41 -> 0.83333333 | G7: 1. Охотно объясняет необходимость и причины изменений/ проясняет ситуацию коллегам/заказчикам на проекте | H7: ='Коллеги_%'!C43 -> 1 | I7: 1. Устраняет противоречия между людьми при помощи аргументов и логики, не переходит на личности | J7: ='Коллеги_%'!C44 -> 1 | K7: 1. Охотно предоставляет помощь и поддержку команде. В случае невозможности помочь, поясняет причины, а не игнорирует
D8: ='Коллеги_%'!C45 -> 0.5 | E8: 2. Понимает ценность выбранного решения для клиента, предпринимает действия для получения заказчиком этой ценности. | F8: ='Коллеги_%'!C50 -> 0.5 | G8: 2. Не избегает конфликта, помнит о целях и интересах проекта. Там, где это необходимо, не боится и отстаивает свою позицию (= не быть всегда на поводу у Клиента) | H8: ='Коллеги_%'!C48 -> 0.33333333 | I8: 2. Видит потребности клиента,которые выходят за скоуп проекта. Проясняет ценность этого для заказчика и возможные способы решения | K8: 2. Выстраивает коммуникацию с коллегами/ заказчиками с учетом их эмоцонального состояния.
D9: ='Коллеги_%'!C46 -> 1 | E9: 3. Честно и открыто излагает свою точку зрения в команде с учетом контекста и эмоционального состояния собеседника | F9: ='Коллеги_%'!C42 -> 0.66666667 | G9: 3. При возникновении конфликта обсуждает возможные пути решения и ищет пути примирения с оппонентами
F10: ='Коллеги_%'!C47 -> 0.33333333 | G10: 4. Самостоятельно выявляет ценность для клиента и предлагает решения
A11: 4 ОТВЕТСТВЕННОСТЬ | B11: ='Коллеги_%'!C74 -> 0.66666667 | C11: 1. Осуществляет регулярный мониторинг и контроль выполнения договоренностей, как со своей стороны | D11: ='Коллеги_%'!C75 -> 1 | E11: 1. Регулярно и системно следует запланированному графику и своевременно сообщает об изменениях/ статусе задачи | G11: 1. Понимает границы своей ответственности на проекте, типы задач, которые требуется выполнять. Отвечает за результаты своей работы, осознавая их влияние на результаты проекта в целом. Берет на себя ответственность за свои ошибочные действия и негативный результат | H11: ='Коллеги_%'!C76 -> 0.83333333 | I11: 1. Занимает проактивную позицию в реализации проекта: делает все необходимое для достижения результата, предвидит и озвучивает риски, предпринимает действия направленные на успешное завершение проекта | J11: ='Коллеги_%'!C83 -> 0.66666667 | K11: Анализирует прошлый период/завершенный проект, делает выводы и делится с коллегами
B12: ='Коллеги_%'!C77 -> 0.83333333 | C12: 2. Учится на своих ошибках и старается не совершать их в дальнейшем | D12: ='Коллеги_%'!C78 -> 1 | E12: 2. Своевременно и открыто заявляет о наличие возникших проблем. Понимает, когда необходимо эскалировать на руководство | F12: ='Коллеги_%'!C80 -> 0.83333333 | G12: 2. В трудной ситуации ищет решение проблемы (собирает информацию, общается с разными людьми, изучает опыт за пределами компании).
B13: ='Коллеги_%'!C84 -> 0.83333333 | C13: 3. Соблюдает принятые в проекте правила (вовремя приходит на работу, соблюдает требования регламентов, заполняет отчеты..), в том числе при взаимодействии с Заказчиком | D13: ='Коллеги_%'!C79 -> 0.83333333 | E13: 3. Проясняет какой конечный результат работы ожидается и в какой срок, фиксирует это. | F13: ='Коллеги_%'!C81 -> 0.83333333 | G13: 3. Продолжает предпринимать попытки добиться результата несмотря на неуспехи
F14: ='Коллеги_%'!C82 -> 0.66666667 | G14: 4. Анализирует сложные ситуации, оценивает риски с целью разрешения ситуации
A15: 5 ПРОВЕДЕНИЕ И УЧАСТИЕ ВО ВСТРЕЧАХ | B15: ='Коллеги_%'!C97 -> 0.5 | C15: 1. Участвует в телефонных конференциях / встречах: способен четко предоставить информацию по заданной теме / вопросу | D15: ='Коллеги_%'!C98 -> 0.33333333 | E15: 1. Организовывает встречи при необходимости: подбирает необходимых участников, выбирает и согласовывает доступное время для всех, формирует список вопросов дляповесткиисоздает приглашение в календаре | G15: 1. Играет роль модератора встречи: четко обозначает повестку, следит за временем, вовлекает необходимых участников в обсуждение, следит за тем, чтобы обсуждение шло согласно цели и возвращает к обсуждению, в случае если участники «уходят» с повестки
D16: ='Коллеги_%'!C100 -> 0.66666667 | E16: 2. Фиксация результатов обсуждения в заданном проектом формате. Если формата нет, то может понятно сформулировать договоренности (действие, срок, ответственный и т п) | F16: ='Коллеги_%'!C101 -> 0.83333333 | G16: 2. Оценивает в ходе эффективность проводимой встречи и при необходимости завершает ее с дальнейшим планом действий или планирует последующий логический follow up
D17: ='Коллеги_%'!C99 -> 0.66666667 | E17: 3. Играет роль модератора встречи: четко обозначает повестку, следит за временем
A18: 6 ВЗАИМОДЕЙСТВИЕ В КОМАНДЕ | B18: ='Коллеги_%'!C57 -> 1 | C18: 1. Всегда предупреждает: о своих отсутствиях на встречах, невозможности выполнить договоренности | D18: ='Коллеги_%'!C58 -> 1 | E18: 1. Открыто говорит о сложностях, с которыми сталкивается в работе, и ищет для них решение | F18: ='Коллеги_%'!C56 -> 1 | G18: 1. Активно участвует в командных обсуждениях | H18: ='Коллеги_%'!C55 -> 1 | I18: 1. Легко общается с людьми любого типа, находит общий язык со многими в проектной команде | J18: ='Коллеги_%'!C69 -> 0.66666667 | K18: 1. Формулирует и доносит правила работы в команде, которые помогают достигать лучшего результата. Пересматривает, делает исключения из правил, если они мешают достижению наилучшего результата
